async 함수 내에서 catch문을 사용해서 에러를 처리하지 않으면 async 함수는 발생한 에러를 reject하는 promise를 반환한다.
따라서 async 함수를 호출하고 Promise.prototype.catch 후속 처리 메서드를 사용해 에러를 캐치할 수 있다.
